<?xml version="1.0" ?>
<robot name="tinyturtle" xmlns:xacro="http://www.ros.org/wiki/xacro">

<xacro:include filename="$(find tinyturtle_description)/urdf/materials.xacro" />
<xacro:include filename="$(find tinyturtle_description)/urdf/tinyturtle.trans" />



<!-- Adding separate files for gazebo materials, physics and plugins -->

<xacro:include filename="$(find tinyturtle_description)/gazebo/tinyturtle_materials.gazebo" />
<xacro:include filename="$(find tinyturtle_description)/gazebo/tinyturtle_physics.gazebo" />
<xacro:include filename="$(find tinyturtle_description)/gazebo/tinyturtle_plugins.gazebo" />


<link name="base_link">
  <inertial>
    <origin xyz="-3.298229312473093e-05 7.810949441360035e-06 0.018308322605156784" rpy="0 0 0"/>
    <mass value="0.0390572753941404"/>
    <inertia ixx="2.4e-05" iyy="5.8e-05" izz="7.9e-05" ixy="-0.0" iyz="0.0" ixz="-0.0"/>
  </inertial>
  <visual>
    <origin xyz="0 0 0" rpy="0 0 0"/>
    <geometry>
      <mesh filename="file://$(find tinyturtle_description)/meshes/base_link.stl" scale="0.001 0.001 0.001"/>
    </geometry>
    <material name="white"/>
  </visual>
  <collision>
    <origin xyz="0 0 0" rpy="0 0 0"/>
    <geometry>
      <mesh filename="file://$(find tinyturtle_description)/meshes/base_link.stl" scale="0.001 0.001 0.001"/>
    </geometry>
  </collision>
</link>

<link name="lidar_1">
  <inertial>
    <origin xyz="-0.020093085214945388 0.020093085214945693 0.009999999999999981" rpy="0 0 0"/>
    <mass value="0.46025861865625706"/>
    <inertia ixx="0.000155" iyy="0.000155" izz="0.00028" ixy="-0.0" iyz="0.0" ixz="0.0"/>
  </inertial>
  <visual>
    <origin xyz="-0.020056 0.020056 -0.1285" rpy="0 0 0"/>
    <geometry>
      <mesh filename="file://$(find tinyturtle_description)/meshes/lidar_1.stl" scale="0.001 0.001 0.001"/>
    </geometry>
    <material name="red"/>
  </visual>
  <collision>
    <origin xyz="-0.020056 0.020056 -0.1285" rpy="0 0 0"/>
    <geometry>
      <mesh filename="file://$(find tinyturtle_description)/meshes/lidar_1.stl" scale="0.001 0.001 0.001"/>
    </geometry>
  </collision>
</link>

<link name="top_station_1">
  <inertial>
    <origin xyz="-0.02534745010068709 -0.0454779047711538 -0.0005106168189151356" rpy="0 0 0"/>
    <mass value="0.020130204219004806"/>
    <inertia ixx="1.7e-05" iyy="1.7e-05" izz="3.3e-05" ixy="0.0" iyz="-0.0" ixz="-0.0"/>
  </inertial>
  <visual>
    <origin xyz="-0.025097 -0.045915 -0.101" rpy="0 0 0"/>
    <geometry>
      <mesh filename="file://$(find tinyturtle_description)/meshes/top_station_1.stl" scale="0.001 0.001 0.001"/>
    </geometry>
    <material name="white"/>
  </visual>
  <collision>
    <origin xyz="-0.025097 -0.045915 -0.101" rpy="0 0 0"/>
    <geometry>
      <mesh filename="file://$(find tinyturtle_description)/meshes/top_station_1.stl" scale="0.001 0.001 0.001"/>
    </geometry>
  </collision>
</link>

<link name="camera_1">
  <inertial>
    <origin xyz="0.0025879539641743277 2.966845066658657e-09 0.002664940085360501" rpy="0 0 0"/>
    <mass value="0.0018521275773336432"/>
    <inertia ixx="0.0" iyy="0.0" izz="0.0" ixy="0.0" iyz="0.0" ixz="0.0"/>
  </inertial>
  <visual>
    <origin xyz="-0.066 -0.000151 -0.072163" rpy="0 0 0"/>
    <geometry>
      <mesh filename="file://$(find tinyturtle_description)/meshes/camera_1.stl" scale="0.001 0.001 0.001"/>
    </geometry>
    <material name="red"/>
  </visual>
  <collision>
    <origin xyz="-0.066 -0.000151 -0.072163" rpy="0 0 0"/>
    <geometry>
      <mesh filename="file://$(find tinyturtle_description)/meshes/camera_1.stl" scale="0.001 0.001 0.001"/>
    </geometry>
  </collision>
</link>

<link name="mid_station_1">
  <inertial>
    <origin xyz="-0.03587245502398578 -0.025070666298246308 0.0027084611097245165" rpy="0 0 0"/>
    <mass value="0.03099638097300552"/>
    <inertia ixx="3.3e-05" iyy="4.5e-05" izz="7.2e-05" ixy="0.0" iyz="-0.0" ixz="-5e-06"/>
  </inertial>
  <visual>
    <origin xyz="-0.044939 -0.025166 -0.061" rpy="0 0 0"/>
    <geometry>
      <mesh filename="file://$(find tinyturtle_description)/meshes/mid_station_1.stl" scale="0.001 0.001 0.001"/>
    </geometry>
    <material name="gold"/>
  </visual>
  <collision>
    <origin xyz="-0.044939 -0.025166 -0.061" rpy="0 0 0"/>
    <geometry>
      <mesh filename="file://$(find tinyturtle_description)/meshes/mid_station_1.stl" scale="0.001 0.001 0.001"/>
    </geometry>
  </collision>
</link>

<link name="left_tire_1">
  <inertial>
    <origin xyz="-1.7066307423074914e-07 0.004500462970665649 4.090547056356808e-07" rpy="0 0 0"/>
    <mass value="0.008294223721002828"/>
    <inertia ixx="2e-06" iyy="3e-06" izz="2e-06" ixy="-0.0" iyz="0.0" ixz="0.0"/>
  </inertial>
  <visual>
    <origin xyz="-3.8e-05 -0.036329 -0.023384" rpy="0 0 0"/>
    <geometry>
      <mesh filename="file://$(find tinyturtle_description)/meshes/left_tire_1.stl" scale="0.001 0.001 0.001"/>
    </geometry>
    <material name="black"/>
  </visual>
  <collision>
    <origin xyz="-3.8e-05 -0.036329 -0.023384" rpy="0 0 0"/>
    <geometry>
      <mesh filename="file://$(find tinyturtle_description)/meshes/left_tire_1.stl" scale="0.001 0.001 0.001"/>
    </geometry>
  </collision>
</link>

<link name="right_tire_1">
  <inertial>
    <origin xyz="-1.8494427270187035e-07 -0.004500462970665649 4.090547056356808e-07" rpy="0 0 0"/>
    <mass value="0.008294223721002828"/>
    <inertia ixx="2e-06" iyy="3e-06" izz="2e-06" ixy="-0.0" iyz="0.0" ixz="0.0"/>
  </inertial>
  <visual>
    <origin xyz="-3.8e-05 0.036329 -0.023384" rpy="0 0 0"/>
    <geometry>
      <mesh filename="file://$(find tinyturtle_description)/meshes/right_tire_1.stl" scale="0.001 0.001 0.001"/>
    </geometry>
    <material name="black"/>
  </visual>
  <collision>
    <origin xyz="-3.8e-05 0.036329 -0.023384" rpy="0 0 0"/>
    <geometry>
      <mesh filename="file://$(find tinyturtle_description)/meshes/right_tire_1.stl" scale="0.001 0.001 0.001"/>
    </geometry>
  </collision>
</link>

<link name="left_wheel_1">
  <inertial>
    <origin xyz="-1.7365974663995543e-07 -0.0034995370293343445 4.0453362134054704e-07" rpy="0 0 0"/>
    <mass value="0.004635401069328985"/>
    <inertia ixx="0.0" iyy="0.0" izz="0.0" ixy="-0.0" iyz="0.0" ixz="0.0"/>
  </inertial>
  <visual>
    <origin xyz="-3.8e-05 -0.043329 -0.023384" rpy="0 0 0"/>
    <geometry>
      <mesh filename="file://$(find tinyturtle_description)/meshes/left_wheel_1.stl" scale="0.001 0.001 0.001"/>
    </geometry>
    <material name="silver"/>
  </visual>
  <collision>
    <origin xyz="-3.8e-05 -0.043329 -0.023384" rpy="0 0 0"/>
    <geometry>
      <mesh filename="file://$(find tinyturtle_description)/meshes/left_wheel_1.stl" scale="0.001 0.001 0.001"/>
    </geometry>
  </collision>
</link>

<link name="right_wheel_1">
  <inertial>
    <origin xyz="-1.8331380826398937e-07 0.0034995370293343514 4.1088276873935126e-07" rpy="0 0 0"/>
    <mass value="0.004635399188258151"/>
    <inertia ixx="0.0" iyy="0.0" izz="0.0" ixy="-0.0" iyz="0.0" ixz="-0.0"/>
  </inertial>
  <visual>
    <origin xyz="-3.8e-05 0.043329 -0.023384" rpy="0 0 0"/>
    <geometry>
      <mesh filename="file://$(find tinyturtle_description)/meshes/right_wheel_1.stl" scale="0.001 0.001 0.001"/>
    </geometry>
    <material name="silver"/>
  </visual>
  <collision>
    <origin xyz="-3.8e-05 0.043329 -0.023384" rpy="0 0 0"/>
    <geometry>
      <mesh filename="file://$(find tinyturtle_description)/meshes/right_wheel_1.stl" scale="0.001 0.001 0.001"/>
    </geometry>
  </collision>
</link>

<joint name="lidar_joint" type="fixed">
  <origin xyz="-0.005041 -0.065971 0.0275" rpy="0 0 0"/>
  <parent link="top_station_1"/>
  <child link="lidar_1"/>
</joint>

<joint name="m2t_joint" type="fixed">
  <origin xyz="-0.019842 0.020749 0.04" rpy="0 0 0"/>
  <parent link="mid_station_1"/>
  <child link="top_station_1"/>
</joint>

<joint name="camera_joint" type="fixed">
  <origin xyz="0.021061 -0.025015 0.011163" rpy="0 0 0"/>
  <parent link="mid_station_1"/>
  <child link="camera_1"/>
</joint>

<joint name="b2m_joint" type="fixed">
  <origin xyz="0.044939 0.025166 0.061" rpy="0 0 0"/>
  <parent link="base_link"/>
  <child link="mid_station_1"/>
</joint>

<joint name="l_w2t_joint" type="fixed">
  <origin xyz="0.0 -0.007 0.0" rpy="0 0 0"/>
  <parent link="left_wheel_1"/>
  <child link="left_tire_1"/>
</joint>

<joint name="r_w2t_joint" type="fixed">
  <origin xyz="0.0 0.007 0.0" rpy="0 0 0"/>
  <parent link="right_wheel_1"/>
  <child link="right_tire_1"/>
</joint>

<joint name="left_motor" type="continuous">
  <origin xyz="3.8e-05 0.043329 0.023384" rpy="0 0 0"/>
  <parent link="base_link"/>
  <child link="left_wheel_1"/>
  <axis xyz="-0.0 1.0 -0.0"/>
</joint>

<joint name="right_motor" type="continuous">
  <origin xyz="3.8e-05 -0.043329 0.023384" rpy="0 0 0"/>
  <parent link="base_link"/>
  <child link="right_wheel_1"/>
  <axis xyz="-0.0 1.0 0.0"/>
</joint>

</robot>
